Workbook

Sheet 00_README
A1: Drona Public School Moodle Master Import Workbook
A3: Updated for Custom Certificate course completion activities. | B3: Single editable Excel control workbook for the Moodle Indian school CLI import CSV pack.
A4: Use course_certificates to review one verified PDF certificate activity per course. | B4: Edit master data and CSV tabs, review Import Sequence and Validation Summary, export the required CSV sheet, then run the CLI dry-run before execute.
A5: Do not change | B5: Do not rename CSV sheets or headers unless you also update the CLI scripts and CSV documentation.
A6: Validation model | B6: Reference lists and validation formulas point from dependent sheets to their master sheets. Dropdowns are applied for common code columns where possible.
A7: Ordered filenames | B7: Export edited CSV sheets using the ordered repository filename shown in 01_IMPORT_SEQUENCE, such as 12_courses.csv or 20_users_students.csv.
A8: Privacy rule | B8: Do not enter full Aadhaar numbers, sensitive medical details, or parent contact data in course content. Use protected profile fields only.
A9: Generated file | B9: /Users/hardik.chauhan/Documents/learning/eLearnMindset/research/drona_public_school/build/workbook_sample/2026-2027/outputs/master-import-workbook/drona_public_school_2026_2027_sample_master.xlsx
A10: Recommended workflow
A11: 1 | B11: Update master lookup sheets first: school, academic years, boards, mediums, grades, streams, divisions, subjects.
A12: 2 | B12: Update generated structure sheets: categories, courses, cohorts, groups.
A13: 3 | B13: Update users, cohort members, role assignments, parent links, and enrolments.
A14: 4 | B14: Update template and academic-year rollover sheets only after the baseline structure is correct.
A15: 5 | B15: Check 03_VALIDATION_SUMMARY for unresolved references.
A16: 6 | B16: Export the required sheet to CSV with the ordered filename from 01_IMPORT_SEQUENCE.
A17: 7 | B17: Run CLI validation and dry-run before production import.

Sheet 01_IMPORT_SEQUENCE
A1: Order | B1: Phase | C1: Ordered CSV file | D1: Logical CSV name | E1: Workbook sheet | F1: Purpose | G1: Depends on | H1: Data rows | I1: Status
A2: 1 | B2: Core master data | C2: 01_school_master.csv | D2: school_master.csv | E2: 05_school_master | F2: School/trust identity and current academic year. | H2: =MAX(0,COUNTA('05_school_master'!$A$2:$A$10000)) | I2: =IF(H2>=0,"Loaded","Check")
A3: 2 | B3: Core master data | C3: 02_academic_years.csv | D3: academic_years.csv | E3: 06_academic_years | F3: Academic-year calendar. | G3: school_master.csv | H3: =MAX(0,COUNTA('06_academic_years'!$A$2:$A$10000)) | I3: =IF(H3>=0,"Loaded","Check")
A4: 3 | B4: Core master data | C4: 03_boards.csv | D4: boards.csv | E4: 07_boards | F4: Education boards. | H4: =MAX(0,COUNTA('07_boards'!$A$2:$A$10000)) | I4: =IF(H4>=0,"Loaded","Check")
A5: 4 | B5: Core master data | C5: 04_mediums.csv | D5: mediums.csv | E5: 08_mediums | F5: Teaching mediums/languages. | H5: =MAX(0,COUNTA('08_mediums'!$A$2:$A$10000)) | I5: =IF(H5>=0,"Loaded","Check")
A6: 5 | B6: Core master data | C6: 05_grades.csv | D6: grades.csv | E6: 09_grades | F6: Grade/class master list. | H6: =MAX(0,COUNTA('09_grades'!$A$2:$A$10000)) | I6: =IF(H6>=0,"Loaded","Check")
A7: 6 | B7: Core master data | C7: 06_streams.csv | D7: streams.csv | E7: 10_streams | F7: Streams such as General, Science, Commerce. | H7: =MAX(0,COUNTA('10_streams'!$A$2:$A$10000)) | I7: =IF(H7>=0,"Loaded","Check")
A8: 7 | B8: Core master data | C8: 07_divisions.csv | D8: divisions.csv | E8: 11_divisions | F8: Class divisions used for Moodle groups. | H8: =MAX(0,COUNTA('11_divisions'!$A$2:$A$10000)) | I8: =IF(H8>=0,"Loaded","Check")
A9: 8 | B9: Core master data | C9: 08_subjects.csv | D9: subjects.csv | E9: 12_subjects | F9: Subject master list. | H9: =MAX(0,COUNTA('12_subjects'!$A$2:$A$10000)) | I9: =IF(H9>=0,"Loaded","Check")
A10: 9 | B10: Core master data | C10: 09_grade_subject_matrix.csv | D10: grade_subject_matrix.csv | E10: 13_grade_subject_matrix | F10: Allowed board/medium/grade/stream/subject combinations. | G10: boards.csv, mediums.csv, grades.csv, streams.csv, subjects.csv | H10: =MAX(0,COUNTA('13_grade_subject_matrix'!$A$2:$A$10000)) | I10: =IF(H10>=0,"Loaded","Check")
A11: 10 | B11: Moodle structure | C11: 10_categories.csv | D11: categories.csv | E11: 14_categories | F11: Moodle course-category hierarchy. | G11: school_master.csv, boards.csv, mediums.csv, grades.csv, streams.csv | H11: =MAX(0,COUNTA('14_categories'!$A$2:$A$10000)) | I11: =IF(H11>=0,"Loaded","Check")
A12: 11 | B12: Moodle structure | C12: 11_optional_year_category_model_categories.csv | D12: optional_year_category_model_categories.csv | E12: 15_optional_year_category_model | F12: Optional year-based category model. | G12: categories.csv, academic_years.csv | H12: =MAX(0,COUNTA('15_optional_year_category_model'!$A$2:$A$10000)) | I12: =IF(H12>=0,"Loaded","Check")
A13: 12 | B13: Moodle structure | C13: 12_courses.csv | D13: courses.csv | E13: 16_courses | F13: Generated Moodle courses. | G13: categories.csv, grade_subject_matrix.csv | H13: =MAX(0,COUNTA('16_courses'!$A$2:$A$10000)) | I13: =IF(H13>=0,"Loaded","Check")
A14: 13 | B14: Moodle structure | C14: 13_courses_with_templatecourse_for_moodle_upload.csv | D14: courses_with_templatecourse_for_moodle_upload.csv | E14: 17_courses_with_templatecourse_ | F14: Moodle native course-upload file using templatecourse. | G14: courses.csv, master_course_template.csv | H14: =MAX(0,COUNTA('17_courses_with_templatecourse_'!$A$2:$A$10000)) | I14: =IF(H14>=0,"Loaded","Check")
A15: 14 | B15: Moodle structure | C15: 14_cohorts.csv | D15: cohorts.csv | E15: 18_cohorts | F15: Student enrolment cohorts. | G15: categories.csv, divisions.csv, academic_years.csv | H15: =MAX(0,COUNTA('18_cohorts'!$A$2:$A$10000)) | I15: =IF(H15>=0,"Loaded","Check")
A16: 15 | B16: Moodle structure | C16: 15_groups.csv | D16: groups.csv | E16: 19_groups | F16: Course-level division groups. | G16: courses.csv, divisions.csv | H16: =MAX(0,COUNTA('19_groups'!$A$2:$A$10000)) | I16: =IF(H16>=0,"Loaded","Check")
A17: 16 | B17: Users and roles | C17: 16_user_profile_fields.csv | D17: user_profile_fields.csv | E17: 20_user_profile_fields | F17: Custom Moodle user-profile fields. | H17: =MAX(0,COUNTA('20_user_profile_fields'!$A$2:$A$10000)) | I17: =IF(H17>=0,"Loaded","Check")
A18: 17 | B18: Users and roles | C18: 17_custom_roles.csv | D18: custom_roles.csv | E18: 21_custom_roles | F18: Custom Moodle roles. | H18: =MAX(0,COUNTA('21_custom_roles'!$A$2:$A$10000)) | I18: =IF(H18>=0,"Loaded","Check")
A19: 18 | B19: Users and roles | C19: 18_role_guidelines.csv | D19: role_guidelines.csv | E19: 22_role_guidelines | F19: Role-assignment guidance. | G19: custom_roles.csv | H19: =MAX(0,COUNTA('22_role_guidelines'!$A$2:$A$10000)) | I19: =IF(H19>=0,"Loaded","Check")
A20: 19 | B20: Users and roles | C20: 19_users_staff.csv | D20: users_staff.csv | E20: 23_users_staff | F20: Staff users. | G20: user_profile_fields.csv | H20: =MAX(0,COUNTA('23_users_staff'!$A$2:$A$10000)) | I20: =IF(H20>=0,"Loaded","Check")
A21: 20 | B21: Users and roles | C21: 20_users_students.csv | D21: users_students.csv | E21: 24_users_students | F21: Student users and school profile fields. | G21: user_profile_fields.csv, cohorts.csv | H21: =MAX(0,COUNTA('24_users_students'!$A$2:$A$10000)) | I21: =IF(H21>=0,"Loaded","Check")
A22: 21 | B22: Users and roles | C22: 21_users_parents.csv | D22: users_parents.csv | E22: 25_users_parents | F22: Parent users. | G22: user_profile_fields.csv | H22: =MAX(0,COUNTA('25_users_parents'!$A$2:$A$10000)) | I22: =IF(H22>=0,"Loaded","Check")
A23: 22 | B23: Users and roles | C23: 22_cohort_members.csv | D23: cohort_members.csv | E23: 26_cohort_members | F23: Student-to-cohort membership. | G23: users_students.csv, cohorts.csv | H23: =MAX(0,COUNTA('26_cohort_members'!$A$2:$A$10000)) | I23: =IF(H23>=0,"Loaded","Check")
A24: 23 | B24: Users and roles | C24: 23_role_assignments.csv | D24: role_assignments.csv | E24: 27_role_assignments | F24: Staff/admin role assignments. | G24: users_staff.csv, custom_roles.csv, categories.csv, courses.csv | H24: =MAX(0,COUNTA('27_role_assignments'!$A$2:$A$10000)) | I24: =IF(H24>=0,"Loaded","Check")
A25: 24 | B25: Users and roles | C25: 24_parent_links.csv | D25: parent_links.csv | E25: 28_parent_links | F25: Parent-child relationships. | G25: users_parents.csv, users_students.csv, custom_roles.csv | H25: =MAX(0,COUNTA('28_parent_links'!$A$2:$A$10000)) | I25: =IF(H25>=0,"Loaded","Check")
A26: 25 | B26: Users and roles | C26: 25_enrolments.csv | D26: enrolments.csv | E26: 29_enrolments | F26: Cohort sync enrolment mappings. | G26: courses.csv, cohorts.csv, groups.csv | H26: =MAX(0,COUNTA('29_enrolments'!$A$2:$A$10000)) | I26: =IF(H26>=0,"Loaded","Check")
A27: 26 | B27: Support | C27: 26_lookup_values.csv | D27: lookup_values.csv | E27: 30_lookup_values | F27: General lookup/reference values. | H27: =MAX(0,COUNTA('30_lookup_values'!$A$2:$A$10000)) | I27: =IF(H27>=0,"Loaded","Check")
A28: 27 | B28: Support | C28: 27_validation_rules.csv | D28: validation_rules.csv | E28: 31_validation_rules | F28: CSV validation rule catalog. | H28: =MAX(0,COUNTA('31_validation_rules'!$A$2:$A$10000)) | I28: =IF(H28>=0,"Loaded","Check")
A29: 28 | B29: Support | C29: 28_source_references.csv | D29: source_references.csv | E29: 32_source_references | F29: Source URL/reference catalog. | H29: =MAX(0,COUNTA('32_source_references'!$A$2:$A$10000)) | I29: =IF(H29>=0,"Loaded","Check")
A30: 29 | B30: Support | C30: 29_summary.csv | D30: summary.csv | E30: 33_summary | F30: Pack summary metrics. | H30: =MAX(0,COUNTA('33_summary'!$A$2:$A$10000)) | I30: =IF(H30>=0,"Loaded","Check")
A31: 30 | B31: Course template | C31: 30_master_course_template.csv | D31: master_course_template.csv | E31: 34_master_course_template | F31: Hidden master course template definition. | H31: =MAX(0,COUNTA('34_master_course_template'!$A$2:$A$10000)) | I31: =IF(H31>=0,"Loaded","Check")
A32: 31 | B32: Course template | C32: 31_course_template_sections.csv | D32: course_template_sections.csv | E32: 35_course_template_sections | F32: Template course sections. | G32: master_course_template.csv | H32: =MAX(0,COUNTA('35_course_template_sections'!$A$2:$A$10000)) | I32: =IF(H32>=0,"Loaded","Check")
A33: 32 | B33: Course template | C33: 32_course_template_activities.csv | D33: course_template_activities.csv | E33: 36_course_template_activities | F33: Template activities and chapter gates. | G33: master_course_template.csv, course_template_sections.csv | H33: =MAX(0,COUNTA('36_course_template_activities'!$A$2:$A$10000)) | I33: =IF(H33>=0,"Loaded","Check")
A34: 33 | B34: Course template | C34: 33_course_template_gradebook.csv | D34: course_template_gradebook.csv | E34: 37_course_template_gradebook | F34: Template gradebook categories. | G34: master_course_template.csv | H34: =MAX(0,COUNTA('37_course_template_gradebook'!$A$2:$A$10000)) | I34: =IF(H34>=0,"Loaded","Check")
A35: 34 | B35: Course template | C35: 34_grade_band_template_adjustments.csv | D35: grade_band_template_adjustments.csv | E35: 38_grade_band_template_adjustme | F35: Grade-band weight and pedagogy adjustments. | G35: course_template_gradebook.csv, grades.csv | H35: =MAX(0,COUNTA('38_grade_band_template_adjustme'!$A$2:$A$10000)) | I35: =IF(H35>=0,"Loaded","Check")
A36: 35 | B36: Course template | C36: 35_subject_template_adjustments.csv | D36: subject_template_adjustments.csv | E36: 39_subject_template_adjustments | F36: Subject-specific template suggestions. | G36: subjects.csv | H36: =MAX(0,COUNTA('39_subject_template_adjustments'!$A$2:$A$10000)) | I36: =IF(H36>=0,"Loaded","Check")
A37: 36 | B37: Course template | C37: 36_completion_tracking_defaults.csv | D37: completion_tracking_defaults.csv | E37: 40_completion_tracking_defaults | F37: Recommended completion settings by activity type. | G37: course_template_activities.csv | H37: =MAX(0,COUNTA('40_completion_tracking_defaults'!$A$2:$A$10000)) | I37: =IF(H37>=0,"Loaded","Check")
A38: 37 | B38: Course template | C38: 37_course_template_application.csv | D38: course_template_application.csv | E38: 41_course_template_application | F38: Map real courses to the master template. | G38: courses.csv, master_course_template.csv | H38: =MAX(0,COUNTA('41_course_template_application'!$A$2:$A$10000)) | I38: =IF(H38>=0,"Loaded","Check")
A39: 38 | B39: Course template | C39: 38_course_template_custom_fields.csv | D39: course_template_custom_fields.csv | E39: 42_course_template_custom_field | F39: Template custom field guidance. | G39: master_course_template.csv | H39: =MAX(0,COUNTA('42_course_template_custom_field'!$A$2:$A$10000)) | I39: =IF(H39>=0,"Loaded","Check")
A40: 39 | B40: Course template | C40: 39_course_template_review_checklist.csv | D40: course_template_review_checklist.csv | E40: 43_course_template_review_check | F40: Template QA checklist. | G40: master_course_template.csv | H40: =MAX(0,COUNTA('43_course_template_review_check'!$A$2:$A$10000)) | I40: =IF(H40>=0,"Loaded","Check")
...

Sheet 02_REFERENCE_RULES
A1: Rule # | B1: Target CSV | C1: Target field | D1: Reference CSV | E1: Reference field | F1: Purpose | G1: Formula pattern
A2: 1 | B2: 09_grade_subject_matrix.csv | C2: board_code | D2: 03_boards.csv | E2: board_code | F2: Board must exist before subject matrix rows. | G2: =IF(LEN('13_grade_subject_matrix'!A2)=0,"Blank",IF(COUNTIF('07_boards'!$A$2:$A$10000,'13_grade_subject_matrix'!A2)>0,"OK","Missing"))
A3: 2 | B3: 09_grade_subject_matrix.csv | C3: medium_code | D3: 04_mediums.csv | E3: medium_code | F3: Medium must exist before subject matrix rows. | G3: =IF(LEN('13_grade_subject_matrix'!B2)=0,"Blank",IF(COUNTIF('08_mediums'!$A$2:$A$10000,'13_grade_subject_matrix'!B2)>0,"OK","Missing"))
A4: 3 | B4: 09_grade_subject_matrix.csv | C4: grade_code | D4: 05_grades.csv | E4: grade_code | F4: Grade must exist before subject matrix rows. | G4: =IF(LEN('13_grade_subject_matrix'!C2)=0,"Blank",IF(COUNTIF('09_grades'!$A$2:$A$10000,'13_grade_subject_matrix'!C2)>0,"OK","Missing"))
A5: 4 | B5: 09_grade_subject_matrix.csv | C5: stream_code | D5: 06_streams.csv | E5: stream_code | F5: Stream must exist before subject matrix rows. | G5: =IF(LEN('13_grade_subject_matrix'!D2)=0,"Blank",IF(COUNTIF('10_streams'!$A$2:$A$10000,'13_grade_subject_matrix'!D2)>0,"OK","Missing"))
A6: 5 | B6: 09_grade_subject_matrix.csv | C6: subject_code | D6: 08_subjects.csv | E6: subject_code | F6: Subject must exist before subject matrix rows. | G6: =IF(LEN('13_grade_subject_matrix'!E2)=0,"Blank",IF(COUNTIF('12_subjects'!$A$2:$A$10000,'13_grade_subject_matrix'!E2)>0,"OK","Missing"))
A7: 6 | B7: 10_categories.csv | C7: parent_category_code | D7: 10_categories.csv | E7: category_code | F7: Parent category must exist in the same category sheet unless blank. | G7: =IF(LEN('14_categories'!B2)=0,"Blank",IF(COUNTIF('14_categories'!$A$2:$A$10000,'14_categories'!B2)>0,"OK","Missing"))
A8: 7 | B8: 12_courses.csv | C8: category_code | D8: 10_categories.csv | E8: category_code | F8: Course category must exist. | G8: =IF(LEN('16_courses'!E2)=0,"Blank",IF(COUNTIF('14_categories'!$A$2:$A$10000,'16_courses'!E2)>0,"OK","Missing"))
A9: 8 | B9: 12_courses.csv | C9: board_code | D9: 03_boards.csv | E9: board_code | F9: Course board must exist. | G9: =IF(LEN('16_courses'!F2)=0,"Blank",IF(COUNTIF('07_boards'!$A$2:$A$10000,'16_courses'!F2)>0,"OK","Missing"))
A10: 9 | B10: 12_courses.csv | C10: medium_code | D10: 04_mediums.csv | E10: medium_code | F10: Course medium must exist. | G10: =IF(LEN('16_courses'!H2)=0,"Blank",IF(COUNTIF('08_mediums'!$A$2:$A$10000,'16_courses'!H2)>0,"OK","Missing"))
A11: 10 | B11: 12_courses.csv | C11: grade_code | D11: 05_grades.csv | E11: grade_code | F11: Course grade must exist. | G11: =IF(LEN('16_courses'!I2)=0,"Blank",IF(COUNTIF('09_grades'!$A$2:$A$10000,'16_courses'!I2)>0,"OK","Missing"))
A12: 11 | B12: 12_courses.csv | C12: stream_code | D12: 06_streams.csv | E12: stream_code | F12: Course stream must exist. | G12: =IF(LEN('16_courses'!J2)=0,"Blank",IF(COUNTIF('10_streams'!$A$2:$A$10000,'16_courses'!J2)>0,"OK","Missing"))
A13: 12 | B13: 12_courses.csv | C13: subject_code | D13: 08_subjects.csv | E13: subject_code | F13: Course subject must exist. | G13: =IF(LEN('16_courses'!K2)=0,"Blank",IF(COUNTIF('12_subjects'!$A$2:$A$10000,'16_courses'!K2)>0,"OK","Missing"))
... A40: 39 | B40: 53_promotion_actions.csv | C40: to_cohort_code | D40: 55_next_year_cohorts_2027_2028.csv | E40: cohort_code | F40: Promotion target cohort must exist. | G40: =IF(LEN('57_promotion_actions'!G2)=0,"Blank",IF(COUNTIF('59_next_year_cohorts_2027_2028'!$A$2:$A$10000,'57_promotion_actions'!G2)>0,"OK","Missing"))

Sheet 03_VALIDATION_SUMMARY
A1: Rule # | B1: Target CSV | C1: Target field | D1: Reference CSV | E1: Reference field | F1: Invalid references | G1: Status
A2: 1 | B2: 09_grade_subject_matrix.csv | C2: board_code | D2: 03_boards.csv | E2: board_code | F2: 0 | G2: OK
A3: 2 | B3: 09_grade_subject_matrix.csv | C3: medium_code | D3: 04_mediums.csv | E3: medium_code | F3: 0 | G3: OK
A4: 3 | B4: 09_grade_subject_matrix.csv | C4: grade_code | D4: 05_grades.csv | E4: grade_code | F4: 0 | G4: OK
A5: 4 | B5: 09_grade_subject_matrix.csv | C5: stream_code | D5: 06_streams.csv | E5: stream_code | F5: 0 | G5: OK
A6: 5 | B6: 09_grade_subject_matrix.csv | C6: subject_code | D6: 08_subjects.csv | E6: subject_code | F6: 0 | G6: OK
A7: 6 | B7: 10_categories.csv | C7: parent_category_code | D7: 10_categories.csv | E7: category_code | F7: 0 | G7: OK
A8: 7 | B8: 12_courses.csv | C8: category_code | D8: 10_categories.csv | E8: category_code | F8: 0 | G8: OK
A9: 8 | B9: 12_courses.csv | C9: board_code | D9: 03_boards.csv | E9: board_code | F9: 0 | G9: OK
A10: 9 | B10: 12_courses.csv | C10: medium_code | D10: 04_mediums.csv | E10: medium_code | F10: 0 | G10: OK
A11: 10 | B11: 12_courses.csv | C11: grade_code | D11: 05_grades.csv | E11: grade_code | F11: 0 | G11: OK
A12: 11 | B12: 12_courses.csv | C12: stream_code | D12: 06_streams.csv | E12: stream_code | F12: 0 | G12: OK
A13: 12 | B13: 12_courses.csv | C13: subject_code | D13: 08_subjects.csv | E13: subject_code | F13: 0 | G13: OK
... A40: 39 | B40: 53_promotion_actions.csv | C40: to_cohort_code | D40: 55_next_year_cohorts_2027_2028.csv | E40: cohort_code | F40: 0 | G40: OK

Sheet status
A1: type | B1: filename | C1: count | D1: status | E1: action
A2: automatic | B2: ALL_AUTOMATIC_SHEETS id_number_formula: rebuild every macro-generated sheet from current master rows | C2: =SUMIF(A7:A2000,"automatic",C7:C2000) | D2: CONTROL | E2: Run all automatic macros: use the macro-enabled .ods workbook
A3: automatic | B3: STATUS_ONLY id_number_formula: recalculate health formulas after manual review | D3: CONTROL | E3: Refresh status: use the macro-enabled .ods workbook
A4: automatic | B4: CLEAR_AUTOMATIC_SHEETS id_number_formula: remove data rows from macro-generated sheets | D4: CONTROL | E4: Clear automatic data: use the macro-enabled .ods workbook
A5: automatic | B5: RESET_AUTOMATIC_SHEETS id_number_formula: clear and regenerate all macro-generated sheets | D5: CONTROL | E5: Reset and regenerate: use the macro-enabled .ods workbook
A7: manual | B7: 01_school_master.csv id_number_formula: Manual/source rows; follow worksheet column contract worksheet: 05_school_master | C7: =COUNTA('05_school_master'!A2:A100000) | D7: MANUAL | E7: Manual edit
A8: manual | B8: 02_academic_years.csv id_number_formula: Manual/source rows; follow worksheet column contract worksheet: 06_academic_years | C8: =COUNTA('06_academic_years'!A2:A100000) | D8: MANUAL | E8: Manual edit
A9: manual | B9: 03_boards.csv id_number_formula: Manual/source rows; follow worksheet column contract worksheet: 07_boards | C9: =COUNTA('07_boards'!A2:A100000) | D9: MANUAL | E9: Manual edit
A10: manual | B10: 04_mediums.csv id_number_formula: Manual/source rows; follow worksheet column contract worksheet: 08_mediums | C10: =COUNTA('08_mediums'!A2:A100000) | D10: MANUAL | E10: Manual edit
A11: manual | B11: 05_grades.csv id_number_formula: Manual/source rows; follow worksheet column contract worksheet: 09_grades | C11: =COUNTA('09_grades'!A2:A100000) | D11: MANUAL | E11: Manual edit
A12: manual | B12: 06_streams.csv id_number_formula: Manual/source rows; follow worksheet column contract worksheet: 10_streams | C12: =COUNTA('10_streams'!A2:A100000) | D12: MANUAL | E12: Manual edit
A13: manual | B13: 07_divisions.csv id_number_formula: Manual/source rows; follow worksheet column contract worksheet: 11_divisions | C13: =COUNTA('11_divisions'!A2:A100000) | D13: MANUAL | E13: Manual edit
A14: manual | B14: 08_subjects.csv id_number_formula: Manual/source rows; follow worksheet column contract worksheet: 12_subjects | C14: =COUNTA('12_subjects'!A2:A100000) | D14: MANUAL | E14: Manual edit
A15: automatic | B15: 09_grade_subject_matrix.csv id_number_formula: <BOARD_CODE>-<MEDIUM_CODE>-<GRADE_CODE>-<STREAM_CODE>-<SUBJECT_CODE> worksheet: 13_grade_subject_matrix | C15: =COUNTA('13_grade_subject_matrix'!A2:A100000) | D15: =IF(C15=(C18),"PASSED","FAILED") | E15: Run macro: use the macro-enabled .ods workbook
A16: automatic | B16: 10_categories.csv id_number_formula: <TRUST_CODE>_<BOARD_CODE>_<SCHOOL_CODE>_<YYYY_YYYY>_<MEDIUM_CODE>_<GRADE_CODE>_<STREAM_CODE> worksheet: 14_categories | C16: =COUNTA('14_categories'!A2:A100000) | D16: =IF(C16>0,"PASSED","FAILED") | E16: Run macro: use the macro-enabled .ods workbook
A17: automatic | B17: 11_optional_year_category_model_categories.csv id_number_formula: <TRUST_CODE>_<BOARD_CODE>_<SCHOOL_CODE>_<YYYY_YYYY>_<MEDIUM_CODE>_<GRADE_CODE>_<STREAM_CODE> worksheet: 15_optional_year_category_model | C17: =COUNTA('15_optional_year_category_model'!A2:A100000) | D17: =IF(C17=(C16),"PASSED","FAILED") | E17: Run macro: use the macro-enabled .ods workbook
A18: automatic | B18: 12_courses.csv id_number_formula: <SCHOOL_CODE>-<BOARD_CODE>-<MEDIUM_CODE>-<GRADE_CODE>-<STREAM_CODE>-<SUBJECT_CODE>-<START_YEAR> worksheet: 16_courses | C18: =COUNTA('16_courses'!A2:A100000) | D18: =IF(C18=(C15),"PASSED","FAILED") | E18: Run macro: use the macro-enabled .ods workbook
A19: automatic | B19: 13_courses_with_templatecourse_for_moodle_upload.csv id_number_formula: <SCHOOL_CODE>-<BOARD_CODE>-<MEDIUM_CODE>-<GRADE_CODE>-<STREAM_CODE>-<SUBJECT_CODE>-<START_YEAR> worksheet: 17_courses_with_templatecourse_ | C19: =COUNTA('17_courses_with_templatecourse_'!A2:A100000) | D19: =IF(C19=(C18),"PASSED","FAILED") | E19: Run macro: use the macro-enabled .ods workbook
A20: automatic | B20: 14_cohorts.csv id_number_formula: <SCHOOL_CODE>-<START_YEAR>-<BOARD_CODE>-<MEDIUM_CODE>-<GRADE_CODE>-<STREAM_CODE>-<DIVISION_CODE> worksheet: 18_cohorts | C20: =COUNTA('18_cohorts'!A2:A100000) | D20: =IF(C20>0,"PASSED","FAILED") | E20: Run macro: use the macro-enabled .ods workbook
A21: automatic | B21: 15_groups.csv id_number_formula: <COURSE_CODE>-<DIVISION_CODE> worksheet: 19_groups | C21: =COUNTA('19_groups'!A2:A100000) | D21: =IF(C21=(C18*COUNTA('11_divisions'!A2:A100000)),"PASSED","FAILED") | E21: Run macro: use the macro-enabled .ods workbook
A22: manual | B22: 16_user_profile_fields.csv id_number_formula: Manual/source rows; follow worksheet column contract worksheet: 20_user_profile_fields | C22: =COUNTA('20_user_profile_fields'!A2:A100000) | D22: MANUAL | E22: Manual edit
A23: manual | B23: 17_custom_roles.csv id_number_formula: Manual/source rows; follow worksheet column contract worksheet: 21_custom_roles | C23: =COUNTA('21_custom_roles'!A2:A100000) | D23: MANUAL | E23: Manual edit
A24: manual | B24: 18_role_guidelines.csv id_number_formula: Manual/source rows; follow worksheet column contract worksheet: 22_role_guidelines | C24: =COUNTA('22_role_guidelines'!A2:A100000) | D24: MANUAL | E24: Manual edit
A25: manual | B25: 19_users_staff.csv id_number_formula: Manual/source rows; follow worksheet column contract worksheet: 23_users_staff | C25: =COUNTA('23_users_staff'!A2:A100000) | D25: MANUAL | E25: Manual edit
A26: manual | B26: 20_users_students.csv id_number_formula: Manual/source rows; follow worksheet column contract worksheet: 24_users_students | C26: =COUNTA('24_users_students'!A2:A100000) | D26: MANUAL | E26: Manual edit
A27: manual | B27: 21_users_parents.csv id_number_formula: Manual/source rows; follow worksheet column contract worksheet: 25_users_parents | C27: =COUNTA('25_users_parents'!A2:A100000) | D27: MANUAL | E27: Manual edit
A28: automatic | B28: 22_cohort_members.csv id_number_formula: <COHORT_CODE> + <STUDENT_USERNAME> worksheet: 26_cohort_members | C28: =COUNTA('26_cohort_members'!A2:A100000) | D28: =IF(C28=(C26),"PASSED","FAILED") | E28: Run macro: use the macro-enabled .ods workbook
A29: manual | B29: 23_role_assignments.csv id_number_formula: Manual/source rows; follow worksheet column contract worksheet: 27_role_assignments | C29: =COUNTA('27_role_assignments'!A2:A100000) | D29: MANUAL | E29: Manual edit
A30: manual | B30: 24_parent_links.csv id_number_formula: Manual/source rows; follow worksheet column contract worksheet: 28_parent_links | C30: =COUNTA('28_parent_links'!A2:A100000) | D30: MANUAL | E30: Manual edit
A31: automatic | B31: 25_enrolments.csv id_number_formula: <COURSE_CODE> + <COHORT_CODE> + cohort_sync worksheet: 29_enrolments | C31: =COUNTA('29_enrolments'!A2:A100000) | D31: =IF(C31=(C21),"PASSED","FAILED") | E31: Run macro: use the macro-enabled .ods workbook
A32: manual | B32: 26_lookup_values.csv id_number_formula: Manual/source rows; follow worksheet column contract worksheet: 30_lookup_values | C32: =COUNTA('30_lookup_values'!A2:A100000) | D32: MANUAL | E32: Manual edit
A33: manual | B33: 27_validation_rules.csv id_number_formula: Manual/source rows; follow worksheet column contract worksheet: 31_validation_rules | C33: =COUNTA('31_validation_rules'!A2:A100000) | D33: MANUAL | E33: Manual edit
A34: manual | B34: 28_source_references.csv id_number_formula: Manual/source rows; follow worksheet column contract worksheet: 32_source_references | C34: =COUNTA('32_source_references'!A2:A100000) | D34: MANUAL | E34: Manual edit
A35: automatic | B35: 29_summary.csv id_number_formula: Generated pack health summary from workbook source rows worksheet: 33_summary | C35: =COUNTA('33_summary'!A2:A100000) | D35: =IF(C35=(8),"PASSED","FAILED") | E35: Run macro: use the macro-enabled .ods workbook
A36: manual | B36: 30_master_course_template.csv id_number_formula: Manual/source rows; follow worksheet column contract worksheet: 34_master_course_template | C36: =COUNTA('34_master_course_template'!A2:A100000) | D36: MANUAL | E36: Manual edit
A37: manual | B37: 31_course_template_sections.csv id_number_formula: Manual/source rows; follow worksheet column contract worksheet: 35_course_template_sections | C37: =COUNTA('35_course_template_sections'!A2:A100000) | D37: MANUAL | E37: Manual edit
A38: manual | B38: 32_course_template_activities.csv id_number_formula: Manual/source rows; follow worksheet column contract worksheet: 36_course_template_activities | C38: =COUNTA('36_course_template_activities'!A2:A100000) | D38: MANUAL | E38: Manual edit
A39: manual | B39: 33_course_template_gradebook.csv id_number_formula: Manual/source rows; follow worksheet column contract worksheet: 37_course_template_gradebook | C39: =COUNTA('37_course_template_gradebook'!A2:A100000) | D39: MANUAL | E39: Manual edit
A40: manual | B40: 34_grade_band_template_adjustments.csv id_number_formula: Manual/source rows; follow worksheet column contract worksheet: 38_grade_band_template_adjustme | C40: =COUNTA('38_grade_band_template_adjustme'!A2:A100000) | D40: MANUAL | E40: Manual edit
A41: manual | B41: 35_subject_template_adjustments.csv id_number_formula: Manual/source rows; follow worksheet column contract worksheet: 39_subject_template_adjustments | C41: =COUNTA('39_subject_template_adjustments'!A2:A100000) | D41: MANUAL | E41: Manual edit
...

Sheet 04_REF_LISTS
A1: board_codes | B1: medium_codes | C1: grade_codes | D1: stream_codes | E1: division_codes | F1: subject_codes | G1: category_codes | H1: course_codes | I1: course_shortnames | J1: cohort_codes | K1: staff_usernames | L1: student_usernames | M1: parent_usernames | N1: role_shortnames | O1: template_codes | P1: academic_years | Q1: next_year_course_codes | R1: next_year_cohort_codes
A2: ='07_boards'!A2 | B2: ='08_mediums'!A2 | C2: ='09_grades'!A2 | D2: ='10_streams'!A2 | E2: ='11_divisions'!A2 | F2: ='12_subjects'!A2 | G2: ='14_categories'!A2 | H2: ='16_courses'!A2 | I2: ='16_courses'!C2 | J2: ='18_cohorts'!A2 | K2: ='23_users_staff'!A2 | L2: ='24_users_students'!A2 | M2: ='25_users_parents'!A2 | N2: ='21_custom_roles'!A2 | O2: ='34_master_course_template'!A2 | P2: ='06_academic_years'!A2 | Q2: ='58_next_year_courses_2027_2028'!A2 | R2: ='59_next_year_cohorts_2027_2028'!A2
A3: ='07_boards'!A3 | B3: ='08_mediums'!A3 | C3: ='09_grades'!A3 | D3: ='10_streams'!A3 | E3: ='11_divisions'!A3 | F3: ='12_subjects'!A3 | G3: ='14_categories'!A3 | H3: ='16_courses'!A3 | I3: ='16_courses'!C3 | J3: ='18_cohorts'!A3 | K3: ='23_users_staff'!A3 | L3: ='24_users_students'!A3 | M3: ='25_users_parents'!A3 | N3: ='21_custom_roles'!A3 | O3: ='34_master_course_template'!A3 | P3: ='06_academic_years'!A3 | Q3: ='58_next_year_courses_2027_2028'!A3 | R3: ='59_next_year_cohorts_2027_2028'!A3
A4: ='07_boards'!A4 | B4: ='08_mediums'!A4 | C4: ='09_grades'!A4 | D4: ='10_streams'!A4 | E4: ='11_divisions'!A4 | F4: ='12_subjects'!A4 | G4: ='14_categories'!A4 | H4: ='16_courses'!A4 | I4: ='16_courses'!C4 | J4: ='18_cohorts'!A4 | K4: ='23_users_staff'!A4 | L4: ='24_users_students'!A4 | M4: ='25_users_parents'!A4 | N4: ='21_custom_roles'!A4 | O4: ='34_master_course_template'!A4 | P4: ='06_academic_years'!A4 | Q4: ='58_next_year_courses_2027_2028'!A4 | R4: ='59_next_year_cohorts_2027_2028'!A4
A5: ='07_boards'!A5 | B5: ='08_mediums'!A5 | C5: ='09_grades'!A5 | D5: ='10_streams'!A5 | E5: ='11_divisions'!A5 | F5: ='12_subjects'!A5 | G5: ='14_categories'!A5 | H5: ='16_courses'!A5 | I5: ='16_courses'!C5 | J5: ='18_cohorts'!A5 | K5: ='23_users_staff'!A5 | L5: ='24_users_students'!A5 | M5: ='25_users_parents'!A5 | N5: ='21_custom_roles'!A5 | O5: ='34_master_course_template'!A5 | P5: ='06_academic_years'!A5 | Q5: ='58_next_year_courses_2027_2028'!A5 | R5: ='59_next_year_cohorts_2027_2028'!A5
A6: ='07_boards'!A6 | B6: ='08_mediums'!A6 | C6: ='09_grades'!A6 | D6: ='10_streams'!A6 | E6: ='11_divisions'!A6 | F6: ='12_subjects'!A6 | G6: ='14_categories'!A6 | H6: ='16_courses'!A6 | I6: ='16_courses'!C6 | J6: ='18_cohorts'!A6 | K6: ='23_users_staff'!A6 | L6: ='24_users_students'!A6 | M6: ='25_users_parents'!A6 | N6: ='21_custom_roles'!A6 | O6: ='34_master_course_template'!A6 | P6: ='06_academic_years'!A6 | Q6: ='58_next_year_courses_2027_2028'!A6 | R6: ='59_next_year_cohorts_2027_2028'!A6
A7: ='07_boards'!A7 | B7: ='08_mediums'!A7 | C7: ='09_grades'!A7 | D7: ='10_streams'!A7 | E7: ='11_divisions'!A7 | F7: ='12_subjects'!A7 | G7: ='14_categories'!A7 | H7: ='16_courses'!A7 | I7: ='16_courses'!C7 | J7: ='18_cohorts'!A7 | K7: ='23_users_staff'!A7 | L7: ='24_users_students'!A7 | M7: ='25_users_parents'!A7 | N7: ='21_custom_roles'!A7 | O7: ='34_master_course_template'!A7 | P7: ='06_academic_years'!A7 | Q7: ='58_next_year_courses_2027_2028'!A7 | R7: ='59_next_year_cohorts_2027_2028'!A7
A8: ='07_boards'!A8 | B8: ='08_mediums'!A8 | C8: ='09_grades'!A8 | D8: ='10_streams'!A8 | E8: ='11_divisions'!A8 | F8: ='12_subjects'!A8 | G8: ='14_categories'!A8 | H8: ='16_courses'!A8 | I8: ='16_courses'!C8 | J8: ='18_cohorts'!A8 | K8: ='23_users_staff'!A8 | L8: ='24_users_students'!A8 | M8: ='25_users_parents'!A8 | N8: ='21_custom_roles'!A8 | O8: ='34_master_course_template'!A8 | P8: ='06_academic_years'!A8 | Q8: ='58_next_year_courses_2027_2028'!A8 | R8: ='59_next_year_cohorts_2027_2028'!A8
A9: ='07_boards'!A9 | B9: ='08_mediums'!A9 | C9: ='09_grades'!A9 | D9: ='10_streams'!A9 | E9: ='11_divisions'!A9 | F9: ='12_subjects'!A9 | G9: ='14_categories'!A9 | H9: ='16_courses'!A9 | I9: ='16_courses'!C9 | J9: ='18_cohorts'!A9 | K9: ='23_users_staff'!A9 | L9: ='24_users_students'!A9 | M9: ='25_users_parents'!A9 | N9: ='21_custom_roles'!A9 | O9: ='34_master_course_template'!A9 | P9: ='06_academic_years'!A9 | Q9: ='58_next_year_courses_2027_2028'!A9 | R9: ='59_next_year_cohorts_2027_2028'!A9
A10: ='07_boards'!A10 | B10: ='08_mediums'!A10 | C10: ='09_grades'!A10 | D10: ='10_streams'!A10 | E10: ='11_divisions'!A10 | F10: ='12_subjects'!A10 | G10: ='14_categories'!A10 | H10: ='16_courses'!A10 | I10: ='16_courses'!C10 | J10: ='18_cohorts'!A10 | K10: ='23_users_staff'!A10 | L10: ='24_users_students'!A10 | M10: ='25_users_parents'!A10 | N10: ='21_custom_roles'!A10 | O10: ='34_master_course_template'!A10 | P10: ='06_academic_years'!A10 | Q10: ='58_next_year_courses_2027_2028'!A10 | R10: ='59_next_year_cohorts_2027_2028'!A10
A11: ='07_boards'!A11 | B11: ='08_mediums'!A11 | C11: ='09_grades'!A11 | D11: ='10_streams'!A11 | E11: ='11_divisions'!A11 | F11: ='12_subjects'!A11 | G11: ='14_categories'!A11 | H11: ='16_courses'!A11 | I11: ='16_courses'!C11 | J11: ='18_cohorts'!A11 | K11: ='23_users_staff'!A11 | L11: ='24_users_students'!A11 | M11: ='25_users_parents'!A11 | N11: ='21_custom_roles'!A11 | O11: ='34_master_course_template'!A11 | P11: ='06_academic_years'!A11 | Q11: ='58_next_year_courses_2027_2028'!A11 | R11: ='59_next_year_cohorts_2027_2028'!A11
A12: ='07_boards'!A12 | B12: ='08_mediums'!A12 | C12: ='09_grades'!A12 | D12: ='10_streams'!A12 | E12: ='11_divisions'!A12 | F12: ='12_subjects'!A12 | G12: ='14_categories'!A12 | H12: ='16_courses'!A12 | I12: ='16_courses'!C12 | J12: ='18_cohorts'!A12 | K12: ='23_users_staff'!A12 | L12: ='24_users_students'!A12 | M12: ='25_users_parents'!A12 | N12: ='21_custom_roles'!A12 | O12: ='34_master_course_template'!A12 | P12: ='06_academic_years'!A12 | Q12: ='58_next_year_courses_2027_2028'!A12 | R12: ='59_next_year_cohorts_2027_2028'!A12
A13: ='07_boards'!A13 | B13: ='08_mediums'!A13 | C13: ='09_grades'!A13 | D13: ='10_streams'!A13 | E13: ='11_divisions'!A13 | F13: ='12_subjects'!A13 | G13: ='14_categories'!A13 | H13: ='16_courses'!A13 | I13: ='16_courses'!C13 | J13: ='18_cohorts'!A13 | K13: ='23_users_staff'!A13 | L13: ='24_users_students'!A13 | M13: ='25_users_parents'!A13 | N13: ='21_custom_roles'!A13 | O13: ='34_master_course_template'!A13 | P13: ='06_academic_years'!A13 | Q13: ='58_next_year_courses_2027_2028'!A13 | R13: ='59_next_year_cohorts_2027_2028'!A13
... A10000: ='07_boards'!A10000 | B10000: ='08_mediums'!A10000 | C10000: ='09_grades'!A10000 | D10000: ='10_streams'!A10000 | E10000: ='11_divisions'!A10000 | F10000: ='12_subjects'!A10000 | G10000: ='14_categories'!A10000 | H10000: ='16_courses'!A10000 | I10000: ='16_courses'!C10000 | J10000: ='18_cohorts'!A10000 | K10000: ='23_users_staff'!A10000 | L10000: ='24_users_students'!A10000 | M10000: ='25_users_parents'!A10000 | N10000: ='21_custom_roles'!A10000 | O10000: ='34_master_course_template'!A10000 | P10000: ='06_academic_years'!A10000 | Q10000: ='58_next_year_courses_2027_2028'!A10000 | R10000: ='59_next_year_cohorts_2027_2028'!A10000

Sheet 05_school_master
A1: trust_code | B1: trust_name | C1: school_code | D1: school_name | E1: udise_code | F1: affiliation_no | G1: school_type | H1: address_line1 | I1: address_line2 | J1: city | K1: district | L1: state | M1: pincode | N1: phone | O1: email | P1: website | Q1: principal_username | R1: academic_year
A2: DRONA_TRUST | B2: Drona Education Trust | C2: DPS | D2: Drona Public School | E2: DPS-DEMO-0001 | F2: GSEB-DEMO-2026 | G2: Private unaided co-educational school | H2: Drona Public School Campus | I2: Near Knowledge Park | J2: Ahmedabad | K2: Ahmedabad | L2: Gujarat | M2: 380015 | N2: +91-79-40000000 | O2: office@dronapublicschool.example | P2: https://dronapublicschool.example | Q2: principal.sharma | R2: 2026-2027

Sheet 06_academic_years
A1: academic_year | B1: start_date | C1: end_date | D1: is_current
A2: 2026-2027 | B2: 2026-04-01 | C2: 2027-03-31 | D2: 1
A3: 2027-2028 | B3: 2027-04-01 | C3: 2028-03-31 | D3: 0
A4: 2028-2029 | B4: 2028-04-01 | C4: 2029-03-31 | D4: 0
A5: 2029-2030 | B5: 2029-04-01 | C5: 2030-03-31 | D5: 0

Sheet 07_boards
A1: board_code | B1: board_name | C1: board_type | D1: country | E1: state | F1: source_url
A2: GSEB | B2: Gujarat Board Education | C2: State Board | D2: India | E2: Gujarat | F2: https://gujarat-education.gov.in/

Sheet 08_mediums
A1: medium_code | B1: medium_name | C1: language_code
A2: GUJ | B2: Gujarati Medium | C2: gu
A3: ENG | B3: English Medium | C3: en
A4: HIN | B4: Hindi Medium | C4: hi

Sheet 09_grades
A1: grade_code | B1: grade_name | C1: display_order | D1: stage | E1: moodle_label
A2: STD01 | B2: Standard 1 | C2: 1 | D2: Primary | E2: Grade 1
A3: STD02 | B3: Standard 2 | C3: 2 | D3: Primary | E3: Grade 2
A4: STD03 | B4: Standard 3 | C4: 3 | D4: Primary | E4: Grade 3
A5: STD04 | B5: Standard 4 | C5: 4 | D5: Primary | E5: Grade 4
A6: STD05 | B6: Standard 5 | C6: 5 | D6: Primary | E6: Grade 5
A7: STD06 | B7: Standard 6 | C7: 6 | D7: Upper Primary | E7: Grade 6
A8: STD07 | B8: Standard 7 | C8: 7 | D8: Upper Primary | E8: Grade 7
A9: STD08 | B9: Standard 8 | C9: 8 | D9: Upper Primary | E9: Grade 8
A10: STD09 | B10: Standard 9 | C10: 9 | D10: Secondary | E10: Grade 9
A11: STD10 | B11: Standard 10 | C11: 10 | D11: Secondary | E11: Grade 10
A12: STD11 | B12: Standard 11 | C12: 11 | D12: Higher Secondary | E12: Grade 11
A13: STD12 | B13: Standard 12 | C13: 12 | D13: Higher Secondary | E13: Grade 12

Sheet 10_streams
A1: stream_code | B1: stream_name | C1: applies_to | D1: notes
A2: GEN | B2: General | C2: STD01-STD10 | D2: General stream for primary, upper primary and secondary grades.
A3: SCI | B3: Science | C3: STD11_SCI|STD12_SCI | D3: Higher secondary Science stream.
A4: COM | B4: Commerce | C4: STD11_COM|STD12_COM | D4: Higher secondary Commerce stream.
A5: ARTS | B5: Arts / Humanities | C5: STD11_ARTS|STD12_ARTS | D5: Higher secondary Arts / Humanities stream.

Sheet 11_divisions
A1: division_code | B1: division_name | C1: display_order
A2: A | B2: Division A | C2: 1
A3: B | B3: Division B | C3: 2
A4: C | B4: Division C | C4: 3
A5: D | B5: Division D | C5: 4
A6: E | B6: Division E | C6: 5
A7: F | B7: Division F | C7: 6

Sheet 12_subjects
A1: subject_code | B1: subject_name | C1: subject_category | D1: notes
A2: ACC | B2: Accountancy | C2: Commerce | D2: Higher secondary accountancy.
A3: ART | B3: Art Education | C3: Co-curricular | D3: Drawing, craft and visual expression.
A4: BA | B4: Business Studies | C4: Commerce | D4: Business organisation and management.
A5: BIO | B5: Biology | C5: Science | D5: Higher secondary biology.
A6: CHEM | B6: Chemistry | C6: Science | D6: Higher secondary chemistry.
A7: CS | B7: Computer Studies | C7: Skill | D7: Computer awareness and digital literacy.
A8: ECO | B8: Economics | C8: Commerce | D8: Economics.
A9: ENG | B9: English | C9: Language | D9: English language and communication.
A10: EVS | B10: Environmental Studies | C10: Core | D10: Environmental studies and local context learning.
A11: GEO | B11: Geography | C11: Arts | D11: Geography.
A12: GUJ | B12: Gujarati | C12: Language | D12: Gujarati language and literature.
... A23: STAT | B23: Statistics | C23: Commerce | D23: Statistics.

Sheet 13_grade_subject_matrix
A1: board_code | B1: medium_code | C1: grade_code | D1: stream_code | E1: subject_code | F1: subject_name | G1: subject_category | H1: is_compulsory | I1: is_elective | J1: display_order | K1: source_note
A2: GSEB | B2: GUJ | C2: STD01 | D2: GEN | E2: GUJ | F2: Gujarati | G2: Language | H2: 1 | I2: 0 | J2: 1 | K2: Generated Gujarat board school local testing subject matrix. Verify exact school subject combinations before production.
A3: GSEB | B3: GUJ | C3: STD01 | D3: GEN | E3: HIN | F3: Hindi | G3: Language | H3: 1 | I3: 0 | J3: 2 | K3: Generated Gujarat board school local testing subject matrix. Verify exact school subject combinations before production.
A4: GSEB | B4: GUJ | C4: STD01 | D4: GEN | E4: ENG | F4: English | G4: Language | H4: 1 | I4: 0 | J4: 3 | K4: Generated Gujarat board school local testing subject matrix. Verify exact school subject combinations before production.
A5: GSEB | B5: GUJ | C5: STD01 | D5: GEN | E5: MATH | F5: Mathematics | G5: Core | H5: 1 | I5: 0 | J5: 4 | K5: Generated Gujarat board school local testing subject matrix. Verify exact school subject combinations before production.
A6: GSEB | B6: GUJ | C6: STD01 | D6: GEN | E6: EVS | F6: Environmental Studies | G6: Core | H6: 1 | I6: 0 | J6: 5 | K6: Generated Gujarat board school local testing subject matrix. Verify exact school subject combinations before production.
A7: GSEB | B7: GUJ | C7: STD01 | D7: GEN | E7: ART | F7: Art Education | G7: Co-curricular | H7: 1 | I7: 0 | J7: 6 | K7: Generated Gujarat board school local testing subject matrix. Verify exact school subject combinations before production.
A8: GSEB | B8: GUJ | C8: STD01 | D8: GEN | E8: PE | F8: Physical Education | G8: Co-curricular | H8: 1 | I8: 0 | J8: 7 | K8: Generated Gujarat board school local testing subject matrix. Verify exact school subject combinations before production.
A9: GSEB | B9: GUJ | C9: STD02 | D9: GEN | E9: GUJ | F9: Gujarati | G9: Language | H9: 1 | I9: 0 | J9: 1 | K9: Generated Gujarat board school local testing subject matrix. Verify exact school subject combinations before production.
A10: GSEB | B10: GUJ | C10: STD02 | D10: GEN | E10: HIN | F10: Hindi | G10: Language | H10: 1 | I10: 0 | J10: 2 | K10: Generated Gujarat board school local testing subject matrix. Verify exact school subject combinations before production.
A11: GSEB | B11: GUJ | C11: STD02 | D11: GEN | E11: ENG | F11: English | G11: Language | H11: 1 | I11: 0 | J11: 3 | K11: Generated Gujarat board school local testing subject matrix. Verify exact school subject combinations before production.
A12: GSEB | B12: GUJ | C12: STD02 | D12: GEN | E12: MATH | F12: Mathematics | G12: Core | H12: 1 | I12: 0 | J12: 4 | K12: Generated Gujarat board school local testing subject matrix. Verify exact school subject combinations before production.
... A201: GSEB | B201: ENG | C201: STD11 | D201: SCI | E201: PHY | F201: Physics | G201: Science | H201: 1 | I201: 0 | J201: 2 | K201: Generated Gujarat board school local testing subject matrix. Verify exact school subject combinations before production.

Sheet 14_categories
A1: category_code | B1: parent_category_code | C1: category_type | D1: name | E1: idnumber | F1: path | G1: visible | H1: description
A2: DRONA_TRUST | C2: trust | D2: Drona Education Trust | E2: DRONA_TRUST | F2: Drona Education Trust | G2: 1 | H2: Root trust category.
A3: DRONA_TRUST_GSEB | B3: DRONA_TRUST | C3: board | D3: Gujarat Board Education | E3: DRONA_TRUST_GSEB | F3: Drona Education Trust / Gujarat Board Education | G3: 1 | H3: Board category.
A4: DRONA_TRUST_GSEB_DPS | B4: DRONA_TRUST_GSEB | C4: school | D4: Drona Public School | E4: DRONA_TRUST_GSEB_DPS | F4: Drona Education Trust / Gujarat Board Education / Drona Public School | G4: 1 | H4: School category.
A5: COURSE_TEMPLATES | C5: system | D5: Course Templates | E5: COURSE_TEMPLATES | F5: Course Templates | G5: 1 | H5: Hidden reusable course templates.
A6: DRONA_TRUST_GSEB_DPS_2026_2027 | B6: DRONA_TRUST_GSEB_DPS | C6: academic_year | D6: Academic Year 2026-2027 | E6: DRONA_TRUST_GSEB_DPS_2026_2027 | F6: Drona Education Trust / Gujarat Board Education / Drona Public School / Academic Year 2026-2027 | G6: 1 | H6: Academic year 2026-2027.
A7: DRONA_TRUST_GSEB_DPS_2026_2027_GUJ | B7: DRONA_TRUST_GSEB_DPS_2026_2027 | C7: medium | D7: Gujarati Medium | E7: DRONA_TRUST_GSEB_DPS_2026_2027_GUJ | F7: Drona Education Trust / Gujarat Board Education / Drona Public School / Academic Year 2026-2027 / Gujarati Medium | G7: 1 | H7: Gujarati Medium category for 2026-2027.
A8: DRONA_TRUST_GSEB_DPS_2026_2027_GUJ_STD01 | B8: DRONA_TRUST_GSEB_DPS_2026_2027_GUJ | C8: grade | D8: Standard 1 | E8: DRONA_TRUST_GSEB_DPS_2026_2027_GUJ_STD01 | F8: Drona Education Trust / Gujarat Board Education / Drona Public School / Academic Year 2026-2027 / Gujarati Medium / Standard 1 | G8: 1 | H8: Standard 1 category.
A9: DRONA_TRUST_GSEB_DPS_2026_2027_GUJ_STD01_GEN | B9: DRONA_TRUST_GSEB_DPS_2026_2027_GUJ_STD01 | C9: stream | D9: General | E9: DRONA_TRUST_GSEB_DPS_2026_2027_GUJ_STD01_GEN | F9: Drona Education Trust / Gujarat Board Education / Drona Public School / Academic Year 2026-2027 / Gujarati Medium / Standard 1 / GEN | G9: 1 | H9: Stream/category for courses.
A10: DRONA_TRUST_GSEB_DPS_2026_2027_GUJ_STD02 | B10: DRONA_TRUST_GSEB_DPS_2026_2027_GUJ | C10: grade | D10: Standard 2 | E10: DRONA_TRUST_GSEB_DPS_2026_2027_GUJ_STD02 | F10: Drona Education Trust / Gujarat Board Education / Drona Public School / Academic Year 2026-2027 / Gujarati Medium / Standard 2 | G10: 1 | H10: Standard 2 category.
A11: DRONA_TRUST_GSEB_DPS_2026_2027_GUJ_STD02_GEN | B11: DRONA_TRUST_GSEB_DPS_2026_2027_GUJ_STD02 | C11: stream | D11: General | E11: DRONA_TRUST_GSEB_DPS_2026_2027_GUJ_STD02_GEN | F11: Drona Education Trust / Gujarat Board Education / Drona Public School / Academic Year 2026-2027 / Gujarati Medium / Standard 2 / GEN | G11: 1 | H11: Stream/category for courses.
A12: DRONA_TRUST_GSEB_DPS_2026_2027_GUJ_STD03 | B12: DRONA_TRUST_GSEB_DPS_2026_2027_GUJ | C12: grade | D12: Standard 3 | E12: DRONA_TRUST_GSEB_DPS_2026_2027_GUJ_STD03 | F12: Drona Education Trust / Gujarat Board Education / Drona Public School / Academic Year 2026-2027 / Gujarati Medium / Standard 3 | G12: 1 | H12: Standard 3 category.
A13: DRONA_TRUST_GSEB_DPS_2026_2027_GUJ_STD03_GEN | B13: DRONA_TRUST_GSEB_DPS_2026_2027_GUJ_STD03 | C13: stream | D13: General | E13: DRONA_TRUST_GSEB_DPS_2026_2027_GUJ_STD03_GEN | F13: Drona Education Trust / Gujarat Board Education / Drona Public School / Academic Year 2026-2027 / Gujarati Medium / Standard 3 / GEN | G13: 1 | H13: Stream/category for courses.
A14: DRONA_TRUST_GSEB_DPS_2026_2027_GUJ_STD04 | B14: DRONA_TRUST_GSEB_DPS_2026_2027_GUJ | C14: grade | D14: Standard 4 | E14: DRONA_TRUST_GSEB_DPS_2026_2027_GUJ_STD04 | F14: Drona Education Trust / Gujarat Board Education / Drona Public School / Academic Year 2026-2027 / Gujarati Medium / Standard 4 | G14: 1 | H14: Standard 4 category.
A15: DRONA_TRUST_GSEB_DPS_2026_2027_GUJ_STD04_GEN | B15: DRONA_TRUST_GSEB_DPS_2026_2027_GUJ_STD04 | C15: stream | D15: General | E15: DRONA_TRUST_GSEB_DPS_2026_2027_GUJ_STD04_GEN | F15: Drona Education Trust / Gujarat Board Education / Drona Public School / Academic Year 2026-2027 / Gujarati Medium / Standard 4 / GEN | G15: 1 | H15: Stream/category for courses.
A16: DRONA_TRUST_GSEB_DPS_2026_2027_GUJ_STD05 | B16: DRONA_TRUST_GSEB_DPS_2026_2027_GUJ | C16: grade | D16: Standard 5 | E16: DRONA_TRUST_GSEB_DPS_2026_2027_GUJ_STD05 | F16: Drona Education Trust / Gujarat Board Education / Drona Public School / Academic Year 2026-2027 / Gujarati Medium / Standard 5 | G16: 1 | H16: Standard 5 category.
A17: DRONA_TRUST_GSEB_DPS_2026_2027_GUJ_STD05_GEN | B17: DRONA_TRUST_GSEB_DPS_2026_2027_GUJ_STD05 | C17: stream | D17: General | E17: DRONA_TRUST_GSEB_DPS_2026_2027_GUJ_STD05_GEN | F17: Drona Education Trust / Gujarat Board Education / Drona Public School / Academic Year 2026-2027 / Gujarati Medium / Standard 5 / GEN | G17: 1 | H17: Stream/category for courses.
... A93: DRONA_TRUST_GSEB_DPS_2026_2027_HIN_STD12_ARTS | B93: DRONA_TRUST_GSEB_DPS_2026_2027_HIN_STD12 | C93: stream | D93: Arts / Humanities | E93: DRONA_TRUST_GSEB_DPS_2026_2027_HIN_STD12_ARTS | F93: Drona Education Trust / Gujarat Board Education / Drona Public School / Academic Year 2026-2027 / Hindi Medium / Standard 12 / ARTS | G93: 1 | H93: Stream/category for courses.

Sheet 15_optional_year_category_model
A1: category_code | B1: parent_category_code | C1: category_type | D1: name | E1: idnumber | F1: path | G1: visible | H1: description
A2: DRONA_TRUST | C2: trust | D2: Drona Education Trust | E2: DRONA_TRUST | F2: Drona Education Trust | G2: 1 | H2: Root trust category.
A3: DRONA_TRUST_GSEB | B3: DRONA_TRUST | C3: board | D3: Gujarat Board Education | E3: DRONA_TRUST_GSEB | F3: Drona Education Trust / Gujarat Board Education | G3: 1 | H3: Board category.
A4: DRONA_TRUST_GSEB_DPS | B4: DRONA_TRUST_GSEB | C4: school | D4: Drona Public School | E4: DRONA_TRUST_GSEB_DPS | F4: Drona Education Trust / Gujarat Board Education / Drona Public School | G4: 1 | H4: School category.
A5: COURSE_TEMPLATES | C5: system | D5: Course Templates | E5: COURSE_TEMPLATES | F5: Course Templates | G5: 1 | H5: Hidden reusable course templates.
A6: DRONA_TRUST_GSEB_DPS_2026_2027 | B6: DRONA_TRUST_GSEB_DPS | C6: academic_year | D6: Academic Year 2026-2027 | E6: DRONA_TRUST_GSEB_DPS_2026_2027 | F6: Drona Education Trust / Gujarat Board Education / Drona Public School / Academic Year 2026-2027 | G6: 1 | H6: Academic year 2026-2027.
A7: DRONA_TRUST_GSEB_DPS_2026_2027_GUJ | B7: DRONA_TRUST_GSEB_DPS_2026_2027 | C7: medium | D7: Gujarati Medium | E7: DRONA_TRUST_GSEB_DPS_2026_2027_GUJ | F7: Drona Education Trust / Gujarat Board Education / Drona Public School / Academic Year 2026-2027 / Gujarati Medium | G7: 1 | H7: Gujarati Medium category for 2026-2027.
A8: DRONA_TRUST_GSEB_DPS_2026_2027_GUJ_STD01 | B8: DRONA_TRUST_GSEB_DPS_2026_2027_GUJ | C8: grade | D8: Standard 1 | E8: DRONA_TRUST_GSEB_DPS_2026_2027_GUJ_STD01 | F8: Drona Education Trust / Gujarat Board Education / Drona Public School / Academic Year 2026-2027 / Gujarati Medium / Standard 1 | G8: 1 | H8: Standard 1 category.
A9: DRONA_TRUST_GSEB_DPS_2026_2027_GUJ_STD01_GEN | B9: DRONA_TRUST_GSEB_DPS_2026_2027_GUJ_STD01 | C9: stream | D9: General | E9: DRONA_TRUST_GSEB_DPS_2026_2027_GUJ_STD01_GEN | F9: Drona Education Trust / Gujarat Board Education / Drona Public School / Academic Year 2026-2027 / Gujarati Medium / Standard 1 / GEN | G9: 1 | H9: Stream/category for courses.
A10: DRONA_TRUST_GSEB_DPS_2026_2027_GUJ_STD02 | B10: DRONA_TRUST_GSEB_DPS_2026_2027_GUJ | C10: grade | D10: Standard 2 | E10: DRONA_TRUST_GSEB_DPS_2026_2027_GUJ_STD02 | F10: Drona Education Trust / Gujarat Board Education / Drona Public School / Academic Year 2026-2027 / Gujarati Medium / Standard 2 | G10: 1 | H10: Standard 2 category.
A11: DRONA_TRUST_GSEB_DPS_2026_2027_GUJ_STD02_GEN | B11: DRONA_TRUST_GSEB_DPS_2026_2027_GUJ_STD02 | C11: stream | D11: General | E11: DRONA_TRUST_GSEB_DPS_2026_2027_GUJ_STD02_GEN | F11: Drona Education Trust / Gujarat Board Education / Drona Public School / Academic Year 2026-2027 / Gujarati Medium / Standard 2 / GEN | G11: 1 | H11: Stream/category for courses.
A12: DRONA_TRUST_GSEB_DPS_2026_2027_GUJ_STD03 | B12: DRONA_TRUST_GSEB_DPS_2026_2027_GUJ | C12: grade | D12: Standard 3 | E12: DRONA_TRUST_GSEB_DPS_2026_2027_GUJ_STD03 | F12: Drona Education Trust / Gujarat Board Education / Drona Public School / Academic Year 2026-2027 / Gujarati Medium / Standard 3 | G12: 1 | H12: Standard 3 category.
A13: DRONA_TRUST_GSEB_DPS_2026_2027_GUJ_STD03_GEN | B13: DRONA_TRUST_GSEB_DPS_2026_2027_GUJ_STD03 | C13: stream | D13: General | E13: DRONA_TRUST_GSEB_DPS_2026_2027_GUJ_STD03_GEN | F13: Drona Education Trust / Gujarat Board Education / Drona Public School / Academic Year 2026-2027 / Gujarati Medium / Standard 3 / GEN | G13: 1 | H13: Stream/category for courses.
A14: DRONA_TRUST_GSEB_DPS_2026_2027_GUJ_STD04 | B14: DRONA_TRUST_GSEB_DPS_2026_2027_GUJ | C14: grade | D14: Standard 4 | E14: DRONA_TRUST_GSEB_DPS_2026_2027_GUJ_STD04 | F14: Drona Education Trust / Gujarat Board Education / Drona Public School / Academic Year 2026-2027 / Gujarati Medium / Standard 4 | G14: 1 | H14: Standard 4 category.
A15: DRONA_TRUST_GSEB_DPS_2026_2027_GUJ_STD04_GEN | B15: DRONA_TRUST_GSEB_DPS_2026_2027_GUJ_STD04 | C15: stream | D15: General | E15: DRONA_TRUST_GSEB_DPS_2026_2027_GUJ_STD04_GEN | F15: Drona Education Trust / Gujarat Board Education / Drona Public School / Academic Year 2026-2027 / Gujarati Medium / Standard 4 / GEN | G15: 1 | H15: Stream/category for courses.
A16: DRONA_TRUST_GSEB_DPS_2026_2027_GUJ_STD05 | B16: DRONA_TRUST_GSEB_DPS_2026_2027_GUJ | C16: grade | D16: Standard 5 | E16: DRONA_TRUST_GSEB_DPS_2026_2027_GUJ_STD05 | F16: Drona Education Trust / Gujarat Board Education / Drona Public School / Academic Year 2026-2027 / Gujarati Medium / Standard 5 | G16: 1 | H16: Standard 5 category.
A17: DRONA_TRUST_GSEB_DPS_2026_2027_GUJ_STD05_GEN | B17: DRONA_TRUST_GSEB_DPS_2026_2027_GUJ_STD05 | C17: stream | D17: General | E17: DRONA_TRUST_GSEB_DPS_2026_2027_GUJ_STD05_GEN | F17: Drona Education Trust / Gujarat Board Education / Drona Public School / Academic Year 2026-2027 / Gujarati Medium / Standard 5 / GEN | G17: 1 | H17: Stream/category for courses.
... A93: DRONA_TRUST_GSEB_DPS_2026_2027_HIN_STD12_ARTS | B93: DRONA_TRUST_GSEB_DPS_2026_2027_HIN_STD12 | C93: stream | D93: Arts / Humanities | E93: DRONA_TRUST_GSEB_DPS_2026_2027_HIN_STD12_ARTS | F93: Drona Education Trust / Gujarat Board Education / Drona Public School / Academic Year 2026-2027 / Hindi Medium / Standard 12 / ARTS | G93: 1 | H93: Stream/category for courses.

Sheet 16_courses
A1: course_code | B1: fullname | C1: shortname | D1: idnumber | E1: category_code | F1: board_code | G1: school_code | H1: medium_code | I1: grade_code | J1: stream_code | K1: subject_code | L1: subject_name | M1: academic_year | N1: format | O1: numsections | P1: visible | Q1: groupmode | R1: groupmodeforce | S1: summary | T1: templatecourse | U1: enablecompletion | V1: showgrades | W1: showreports | X1: tags | Y1: course_template_code | Z1: term
A2: DPS-GSEB-GUJ-STD01-GEN-GUJ-2026 | B2: Drona Public School - Gujarat Board Education - Gujarati Medium - Standard 1 - GEN - Gujarati - 2026-2027 | C2: DPS-GSEB-GUJ-STD01-GEN-GUJ-26 | D2: DPS-GSEB-GUJ-STD01-GEN-GUJ-2026 | E2: DRONA_TRUST_GSEB_DPS_2026_2027_GUJ_STD01_GEN | F2: GSEB | G2: DPS | H2: GUJ | I2: STD01 | J2: GEN | K2: GUJ | L2: Gujarati | M2: 2026-2027 | N2: topics | O2: 16 | P2: 1 | Q2: 1 | R2: 1 | S2: Gujarati course for Standard 1 GEN Gujarati Medium in 2026-2027. Includes 10 chapter structure, term exams, final exam, completion rules and default certification. | T2: MASTER-ALL-GRADES-ALL-SUBJECTS-STD-TEMPLATE | U2: 1 | V2: 1 | W2: 1 | X2: DPS,GSEB,2026-2027,GUJ,STD01,GEN,GUJ | Y2: TPL_STD01_02_ACTIVITY | Z2: Academic Year 2026-2027
A3: DPS-GSEB-GUJ-STD01-GEN-HIN-2026 | B3: Drona Public School - Gujarat Board Education - Gujarati Medium - Standard 1 - GEN - Hindi - 2026-2027 | C3: DPS-GSEB-GUJ-STD01-GEN-HIN-26 | D3: DPS-GSEB-GUJ-STD01-GEN-HIN-2026 | E3: DRONA_TRUST_GSEB_DPS_2026_2027_GUJ_STD01_GEN | F3: GSEB | G3: DPS | H3: GUJ | I3: STD01 | J3: GEN | K3: HIN | L3: Hindi | M3: 2026-2027 | N3: topics | O3: 16 | P3: 1 | Q3: 1 | R3: 1 | S3: Hindi course for Standard 1 GEN Gujarati Medium in 2026-2027. Includes 10 chapter structure, term exams, final exam, completion rules and default certification. | T3: MASTER-ALL-GRADES-ALL-SUBJECTS-STD-TEMPLATE | U3: 1 | V3: 1 | W3: 1 | X3: DPS,GSEB,2026-2027,GUJ,STD01,GEN,HIN | Y3: TPL_STD01_02_ACTIVITY | Z3: Academic Year 2026-2027
A4: DPS-GSEB-GUJ-STD01-GEN-ENG-2026 | B4: Drona Public School - Gujarat Board Education - Gujarati Medium - Standard 1 - GEN - English - 2026-2027 | C4: DPS-GSEB-GUJ-STD01-GEN-ENG-26 | D4: DPS-GSEB-GUJ-STD01-GEN-ENG-2026 | E4: DRONA_TRUST_GSEB_DPS_2026_2027_GUJ_STD01_GEN | F4: GSEB | G4: DPS | H4: GUJ | I4: STD01 | J4: GEN | K4: ENG | L4: English | M4: 2026-2027 | N4: topics | O4: 16 | P4: 1 | Q4: 1 | R4: 1 | S4: English course for Standard 1 GEN Gujarati Medium in 2026-2027. Includes 10 chapter structure, term exams, final exam, completion rules and default certification. | T4: MASTER-ALL-GRADES-ALL-SUBJECTS-STD-TEMPLATE | U4: 1 | V4: 1 | W4: 1 | X4: DPS,GSEB,2026-2027,GUJ,STD01,GEN,ENG | Y4: TPL_STD01_02_ACTIVITY | Z4: Academic Year 2026-2027
A5: DPS-GSEB-GUJ-STD01-GEN-MATH-2026 | B5: Drona Public School - Gujarat Board Education - Gujarati Medium - Standard 1 - GEN - Mathematics - 2026-2027 | C5: DPS-GSEB-GUJ-STD01-GEN-MATH-26 | D5: DPS-GSEB-GUJ-STD01-GEN-MATH-2026 | E5: DRONA_TRUST_GSEB_DPS_2026_2027_GUJ_STD01_GEN | F5: GSEB | G5: DPS | H5: GUJ | I5: STD01 | J5: GEN | K5: MATH | L5: Mathematics | M5: 2026-2027 | N5: topics | O5: 16 | P5: 1 | Q5: 1 | R5: 1 | S5: Mathematics course for Standard 1 GEN Gujarati Medium in 2026-2027. Includes 10 chapter structure, term exams, final exam, completion rules and default certification. | T5: MASTER-ALL-GRADES-ALL-SUBJECTS-STD-TEMPLATE | U5: 1 | V5: 1 | W5: 1 | X5: DPS,GSEB,2026-2027,GUJ,STD01,GEN,MATH | Y5: TPL_STD01_02_ACTIVITY | Z5: Academic Year 2026-2027
A6: DPS-GSEB-GUJ-STD01-GEN-EVS-2026 | B6: Drona Public School - Gujarat Board Education - Gujarati Medium - Standard 1 - GEN - Environmental Studies - 2026-2027 | C6: DPS-GSEB-GUJ-STD01-GEN-EVS-26 | D6: DPS-GSEB-GUJ-STD01-GEN-EVS-2026 | E6: DRONA_TRUST_GSEB_DPS_2026_2027_GUJ_STD01_GEN | F6: GSEB | G6: DPS | H6: GUJ | I6: STD01 | J6: GEN | K6: EVS | L6: Environmental Studies | M6: 2026-2027 | N6: topics | O6: 16 | P6: 1 | Q6: 1 | R6: 1 | S6: Environmental Studies course for Standard 1 GEN Gujarati Medium in 2026-2027. Includes 10 chapter structure, term exams, final exam, completion rules and default certification. | T6: MASTER-ALL-GRADES-ALL-SUBJECTS-STD-TEMPLATE | U6: 1 | V6: 1 | W6: 1 | X6: DPS,GSEB,2026-2027,GUJ,STD01,GEN,EVS | Y6: TPL_STD01_02_ACTIVITY | Z6: Academic Year 2026-2027
A7: DPS-GSEB-GUJ-STD01-GEN-ART-2026 | B7: Drona Public School - Gujarat Board Education - Gujarati Medium - Standard 1 - GEN - Art Education - 2026-2027 | C7: DPS-GSEB-GUJ-STD01-GEN-ART-26 | D7: DPS-GSEB-GUJ-STD01-GEN-ART-2026 | E7: DRONA_TRUST_GSEB_DPS_2026_2027_GUJ_STD01_GEN | F7: GSEB | G7: DPS | H7: GUJ | I7: STD01 | J7: GEN | K7: ART | L7: Art Education | M7: 2026-2027 | N7: topics | O7: 16 | P7: 1 | Q7: 1 | R7: 1 | S7: Art Education course for Standard 1 GEN Gujarati Medium in 2026-2027. Includes 10 chapter structure, term exams, final exam, completion rules and default certification. | T7: MASTER-ALL-GRADES-ALL-SUBJECTS-STD-TEMPLATE | U7: 1 | V7: 1 | W7: 1 | X7: DPS,GSEB,2026-2027,GUJ,STD01,GEN,ART | Y7: TPL_STD01_02_ACTIVITY | Z7: Academic Year 2026-2027
A8: DPS-GSEB-GUJ-STD01-GEN-PE-2026 | B8: Drona Public School - Gujarat Board Education - Gujarati Medium - Standard 1 - GEN - Physical Education - 2026-2027 | C8: DPS-GSEB-GUJ-STD01-GEN-PE-26 | D8: DPS-GSEB-GUJ-STD01-GEN-PE-2026 | E8: DRONA_TRUST_GSEB_DPS_2026_2027_GUJ_STD01_GEN | F8: GSEB | G8: DPS | H8: GUJ | I8: STD01 | J8: GEN | K8: PE | L8: Physical Education | M8: 2026-2027 | N8: topics | O8: 16 | P8: 1 | Q8: 1 | R8: 1 | S8: Physical Education course for Standard 1 GEN Gujarati Medium in 2026-2027. Includes 10 chapter structure, term exams, final exam, completion rules and default certification. | T8: MASTER-ALL-GRADES-ALL-SUBJECTS-STD-TEMPLATE | U8: 1 | V8: 1 | W8: 1 | X8: DPS,GSEB,2026-2027,GUJ,STD01,GEN,PE | Y8: TPL_STD01_02_ACTIVITY | Z8: Academic Year 2026-2027
A9: DPS-GSEB-GUJ-STD02-GEN-GUJ-2026 | B9: Drona Public School - Gujarat Board Education - Gujarati Medium - Standard 2 - GEN - Gujarati - 2026-2027 | C9: DPS-GSEB-GUJ-STD02-GEN-GUJ-26 | D9: DPS-GSEB-GUJ-STD02-GEN-GUJ-2026 | E9: DRONA_TRUST_GSEB_DPS_2026_2027_GUJ_STD02_GEN | F9: GSEB | G9: DPS | H9: GUJ | I9: STD02 | J9: GEN | K9: GUJ | L9: Gujarati | M9: 2026-2027 | N9: topics | O9: 16 | P9: 1 | Q9: 1 | R9: 1 | S9: Gujarati course for Standard 2 GEN Gujarati Medium in 2026-2027. Includes 10 chapter structure, term exams, final exam, completion rules and default certification. | T9: MASTER-ALL-GRADES-ALL-SUBJECTS-STD-TEMPLATE | U9: 1 | V9: 1 | W9: 1 | X9: DPS,GSEB,2026-2027,GUJ,STD02,GEN,GUJ | Y9: TPL_STD01_02_ACTIVITY | Z9: Academic Year 2026-2027
